Traceback (most recent call last):
  File "/shared/ifbstor1/software/miniconda/envs/jupyter-book-0.13.1/lib/python3.10/site-packages/jupyter_cache/executors/utils.py", line 51, in single_nb_execution
    executenb(
  File "/shared/ifbstor1/software/miniconda/envs/jupyter-book-0.13.1/lib/python3.10/site-packages/nbclient/client.py", line 1204, in execute
    return NotebookClient(nb=nb, resources=resources, km=km, **kwargs).execute()
  File "/shared/ifbstor1/software/miniconda/envs/jupyter-book-0.13.1/lib/python3.10/site-packages/nbclient/util.py", line 84, in wrapped
    return just_run(coro(*args, **kwargs))
  File "/shared/ifbstor1/software/miniconda/envs/jupyter-book-0.13.1/lib/python3.10/site-packages/nbclient/util.py", line 62, in just_run
    return loop.run_until_complete(coro)
  File "/shared/ifbstor1/software/miniconda/envs/jupyter-book-0.13.1/lib/python3.10/asyncio/base_events.py", line 646, in run_until_complete
    return future.result()
  File "/shared/ifbstor1/software/miniconda/envs/jupyter-book-0.13.1/lib/python3.10/site-packages/nbclient/client.py", line 663, in async_execute
    await self.async_execute_cell(
  File "/shared/ifbstor1/software/miniconda/envs/jupyter-book-0.13.1/lib/python3.10/site-packages/nbclient/client.py", line 965, in async_execute_cell
    await self._check_raise_for_error(cell, cell_index, exec_reply)
  File "/shared/ifbstor1/software/miniconda/envs/jupyter-book-0.13.1/lib/python3.10/site-packages/nbclient/client.py", line 862, in _check_raise_for_error
    raise CellExecutionError.from_cell_and_msg(cell, exec_reply_content)
nbclient.exceptions.CellExecutionError: An error occurred while executing the following cell:
------------------
# Recap 


```{glossary}
IRI
    International Resource Identifier == URI allowing international characters
RDF
    Resource Description Framework
```
------------------

[0;36m  Cell [0;32mIn[6], line 4[0;36m[0m
[0;31m    ```{glossary}[0m
[0m    ^[0m
[0;31mSyntaxError[0m[0;31m:[0m invalid syntax

SyntaxError: invalid syntax (1643443517.py, line 4)

